Workbook

Sheet Dashboard
A1: Real-Time Stock Monitor
A2: TOTAL TANK STOCK (L) | H2: TANK 1 VARIANCE | N2: TOTAL BOWSER STOCK (L) | Z2: VOLUME SOLD TODAY | AF2: =CONCATENATE("VOLUME SOLD:"," ",AL11,","," ",AL9," ","TO"," ",AO11,","," ",AO9) -> VOLUME SOLD: SEP, 1 TO SEP, 16 | AL2: =CONCATENATE(AC7,":"," ",AL11,","," ",AL9," ","TO"," ",AO11,","," ",AO9) -> ETHIOPIAN: SEP, 1 TO SEP, 16
A3: =IFERROR(sum(StockOverview!B5:B7),"Check Data") -> 268642 | N3: =IFERROR(SUM(StockOverview!B12:B19),"") -> 277335 | Z3: =SUMIFS(Sales!I:I,Sales!A:A,">="& AL6, Sales!A:A, "<"& AO6) -> 0 | AF3: =IF(OR(AO17="❌ Invalid",AO18="❌Invalid"),"⚠️ Please select valid dates",SUMIFS(Sales!I:I,Sales!A:A, ">=" & AL15,Sales!A:A, "<" & AO15 + 1)) -> 2148606 | AL3: =IF(OR(AO17="❌ Invalid",AO18="❌Invalid"),"⚠️ Please select valid dates",SUMIFS(Sales!I:I,Sales!A:A, ">=" & AL15,Sales!A:A, "<" & AO15+1,Sales!F:F,AC7)) -> 792553
AL5: CURRENT SHIFT CYCLE
B6: TANK STOCK LEVELS | T6: Tank ID | X6: Volume (L) | AC6: Select Airline | AL6: =IF(TIMEVALUE(NOW()) < TIME(8,0,0), TODAY()-1+TIME(8,0,0), TODAY()+TIME(8,0,0)) -> 45921.333 | AO6: =AL6+1 -> 45922.333
T7: Tank 1 | X7: =StockOverview!H5+SUMIFS(TSM!K:K,TSM!D:D,T7,TSM!A:A,">="&AL6,TSM!Q:Q,"Inflow")-SUMIFS(TSM!K:K,TSM!D:D,T7,TSM!A:A,">="&AL6,TSM!Q:Q,"Outflow") -> 0 | AC7: ETHIOPIAN | AL7: Date Combination
T8: Tank 2 | X8: =StockOverview!H6+SUMIFS(TSM!K:K,TSM!D:D,T8,TSM!A:A,">="&AL6,TSM!Q:Q,"Inflow")-SUMIFS(TSM!K:K,TSM!D:D,T8,TSM!A:A,">="&AL6,TSM!Q:Q,"Outflow") -> 0 | AL8: Start Day | AO8: End Day
T9: Tank 3 | X9: =StockOverview!H7+SUMIFS(TSM!K:K,TSM!D:D,T9,TSM!A:A,">="&AL6,TSM!Q:Q,"Inflow")-SUMIFS(TSM!K:K,TSM!D:D,T9,TSM!A:A,">="&AL6,TSM!Q:Q,"Outflow") -> 268642 | AC9: Bowser ID | AG9: Volume (L) | AL9: 1 | AO9: 16
AC10: Adeyemi | AG10: =VLOOKUP(AC10,StockOverview!A11:B11,2,false) -> #N/A | AL10: Start Month | AO10: End Month
T11: Tank Stock Movement | AC11: Akachi | AG11: =VLOOKUP(AC11,StockOverview!A12:B20,2,false) -> 35161 | AL11: SEP | AO11: SEP
T12: Total Inflow | AC12: Ashake | AG12: =VLOOKUP(AC12,StockOverview!A13:B20,2,false) -> 5493 | AL12: Start Year | AO12: End Year
T13: Expected | X13: =SUMIFS(TSM!G:G,TSM!A:A,">="&AL6,TSM!Q:Q,"Inflow") -> 0 | AC13: Divine grace | AG13: =VLOOKUP(AC13,StockOverview!A14:B20,2,false) -> 54990 | AL13: 2025 | AO13: 2025
T14: Actual | X14: =SUMIFS(TSM!K:K,TSM!A:A,">="&AL6,TSM!Q:Q,"Inflow") -> 0 | AC14: Odogwu | AG14: =VLOOKUP(AC14,#REF!,2,false) -> #REF! | AL14: Start Date | AO14: End Date
T15: Total Outflow | AC15: Roseline | AG15: =VLOOKUP(AC15,StockOverview!A22:B22,2,false) -> #N/A | AL15: {=IF(AO17="❌ Invalid Start Date","", DATE(AL13, MATCH(AL11, {"Jan","Feb","Mar","Apr","May","Jun","Jul","Aug","Sep","Oct","Nov","Dec"},0), AL9) + TIME(8,0,0))} -> 45901.333 | AO15: {=IF(AO18="❌ Invalid End Date","", DATE(AO13, MATCH(AO11, {"Jan","Feb","Mar","Apr","May","Jun","Jul","Aug","Sep","Oct","Nov","Dec"},0), AO9) + TIME(8,0,0))} -> 45916.333
T16: Expected | X16: =SUMIFS(TSM!G:G,TSM!A:A,">="&AL6,TSM!Q:Q,"Outflow") -> 0 | AC16: Seriki | AG16: =VLOOKUP(AC16,StockOverview!A22:B23,2,false) -> #N/A | AL16: Date Validity
T17: Actual | X17: =SUMIFS(TSM!K:K,TSM!A:A,">="&AL6,TSM!Q:Q,"Outflow") -> 0 | AC17: Sultan | AG17: =VLOOKUP(AC17,StockOverview!A22:B24,2,false) -> #N/A | AL17: Start Date | AO17: {=IF(AL9>DAY(EOMONTH(DATE(AL13, MATCH(AL11, {"Jan","Feb","Mar","Apr","May","Jun","Jul","Aug","Sep","Oct","Nov","Dec"},0), 1), 0)), "❌ Invalid", "✓ Valid")} -> ✓ Valid
T18: Dip Value | AL18: End Date | AO18: {=IF(AO9>DAY(EOMONTH(DATE(AO13, MATCH(AO11, {"Jan","Feb","Mar","Apr","May","Jun","Jul","Aug","Sep","Oct","Nov","Dec"},0), 1), 0)), "❌ Invalid", "✓ Valid")} -> ✓ Valid

Sheet Copy of Dashboard
A1: Real-Time Stock Monitor
A2: TOTAL TANK STOCK (L) | H2: TANK 1 VARIANCE | N2: TOTAL BOWSER STOCK (L) | Z2: VOLUME SOLD TODAY | AF2: =CONCATENATE("VOLUME SOLD:"," ",AL11,","," ",AL9," ","TO"," ",AO11,","," ",AO9) -> VOLUME SOLD: SEP, 20 TO SEP, 20 | AL2: =CONCATENATE(AC7,":"," ",AL11,","," ",AL9," ","TO"," ",AO11,","," ",AO9) -> ETHIOPIAN: SEP, 20 TO SEP, 20
A3: =IFERROR(sum(StockOverview!B5:B7),"Check Data") -> 268642 | H3: =IF(OR(AO17="❌ Invalid",AO18="❌Invalid"),"⚠️ Please select valid dates",IFS(H2:M2="TANK 1 VARIANCE",SUMIFS(TSM!L:L,TSM!D:D,"Tank 1",TSM!A:A,">=" & AL15,TSM!A:A, "<" & AO15 + 1),H2:M2="TANK 2 VARIANCE",SUMIFS(TSM!L:L,TSM!D:D,"Tank 2",TSM!A:A,">=" & AL15,TSM!A:A, "<" & AO15 + 1),H2:M2="TANK 3 VARIANCE",SUMIFS(TSM!L:L,TSM!D:D,"Tank 3",TSM!A:A,">=" & AL15,TSM!A:A, "<" & AO15 + 1),H2:M2="TOTAL TANK VARIANCE",SUMIFS(TSM!L:L,TSM!A:A,">=" & AL15,TSM!A:A, "<" & AO15 + 1))) -> 0 | N3: =IFERROR(SUM(StockOverview!B12:B19),"") -> 277335 | Z3: =SUMIFS(Sales!I:I,Sales!A:A,">="& AL6, Sales!A:A, "<"& AO6) -> 0 | AF3: =IF(OR(AO17="❌ Invalid",AO18="❌Invalid"),"⚠️ Please select valid dates",SUMIFS(Sales!I:I,Sales!A:A,">=" & AL15,Sales!A:A, "<" & AO15 + 1)) -> 0 | AL3: =IF(OR(AO17="❌ Invalid",AO18="❌Invalid"),"⚠️ Please select valid dates",SUMIFS(Sales!I:I,Sales!A:A, ">=" & AL15,Sales!A:A, "<" & AO15+1,Sales!F:F,AC7)) -> 0
AL5: CURRENT SHIFT CYCLE
B6: TANK STOCK LEVELS | T6: Tank ID | X6: Volume (L) | AC6: Select Airline | AL6: =IF(TIMEVALUE(NOW()) < TIME(8,0,0), TODAY()-1+TIME(8,0,0), TODAY()+TIME(8,0,0)) -> 45921.333 | AO6: =AL6+1 -> 45922.333
T7: Tank 1 | X7: =StockOverview!B5 -> 0 | AC7: ETHIOPIAN | AL7: Date Combination
T8: Tank 2 | X8: =StockOverview!B6 -> 0 | AC8: =IFERROR(__xludf.DUMMYFUNCTION("IF(OR(AO17=""❌ Invalid"",AO18=""❌Invalid""),""⚠️ Please select valid dates"",vlookup(min(filter(TSM!A:A,TSM!A:A>=AL15,TSM!A:A<AO15 + 1)),TSM!A:Q,8,FALSE)+SUMIFS(TSM!G:G,TSM!A:A,"">="" & AL15,TSM!A:A, ""<"" & AO15 + 1,TSM!Q:Q,""Inflow""))-SUMIFS(TSM!G:G,TS"&"M!A:A,"">="" & AL15,TSM!A:A, ""<"" & AO15 + 1,TSM!Q:Q,""Outflow"")"),"#N/A") -> #N/A | AL8: Start Day | AO8: End Day
T9: Tank 3 | X9: =StockOverview!B7 -> 268642 | AC9: Bowser ID | AG9: Volume (L) | AL9: 20 | AO9: 20
AC10: Adeyemi | AG10: =IFERROR(VLOOKUP(MAXIFS(TSM!A:A,TSM!F:F,AC10),TSM!A:Q,14,FALSE),"") -> 54596 | AL10: Start Month | AO10: End Month
T11: Tank Stock Movement | AC11: Akachi | AG11: =IFERROR(VLOOKUP(MAXIFS(TSM!A:A,TSM!F:F,AC11),TSM!A:Q,14,FALSE),"") -> 35161 | AL11: SEP | AO11: SEP
T12: Total Inflow Today | AC12: Ashake | AG12: =IFERROR(VLOOKUP(MAXIFS(TSM!A:A,TSM!F:F,AC12),TSM!A:Q,14,FALSE),"") -> 5493 | AL12: Start Year | AO12: End Year
T13: Expected | X13: =SUMIFS(TSM!G:G,TSM!A:A,">="&AL6,TSM!Q:Q,"Inflow") -> 0 | AC13: Divine grace | AG13: =IFERROR(VLOOKUP(MAXIFS(TSM!A:A,TSM!F:F,AC13),TSM!A:Q,14,FALSE),"") -> 54990 | AL13: 2025 | AO13: 2025
T14: Actual | X14: =SUMIFS(TSM!K:K,TSM!A:A,">="&AL6,TSM!Q:Q,"Inflow") -> 0 | AC14: Odogwu | AG14: =IFERROR(VLOOKUP(MAXIFS(TSM!A:A,TSM!F:F,AC14),TSM!A:Q,14,FALSE),"") -> 41009 | AL14: Start Date | AO14: End Date
T15: Total Outflow Today | AC15: Roseline | AG15: =IFERROR(VLOOKUP(MAXIFS(TSM!A:A,TSM!F:F,AC15),TSM!A:Q,14,FALSE),"") | AL15: {=IF(AO17="❌ Invalid Start Date","", DATE(AL13, MATCH(AL11, {"Jan","Feb","Mar","Apr","May","Jun","Jul","Aug","Sep","Oct","Nov","Dec"},0), AL9) + TIME(8,0,0))} -> 45920.333 | AO15: {=IF(AO18="❌ Invalid End Date","", DATE(AO13, MATCH(AO11, {"Jan","Feb","Mar","Apr","May","Jun","Jul","Aug","Sep","Oct","Nov","Dec"},0), AO9) + TIME(8,0,0))} -> 45920.333
T16: Expected | X16: =SUMIFS(TSM!G:G,TSM!A:A,">="&AL6,TSM!Q:Q,"Outflow") -> 0 | AC16: Seriki | AG16: =IFERROR(VLOOKUP(MAXIFS(TSM!A:A,TSM!F:F,AC16),TSM!A:Q,14,FALSE),"") -> 31086 | AL16: Date Validity
T17: Actual | X17: =SUMIFS(TSM!K:K,TSM!A:A,">="&AL6,TSM!Q:Q,"Outflow") -> 0 | AC17: Sultan | AG17: =IFERROR(VLOOKUP(MAXIFS(TSM!A:A,TSM!F:F,AC17),TSM!A:Q,14,FALSE),"") -> 55000 | AL17: Start Date | AO17: {=IF(AL9>DAY(EOMONTH(DATE(AL13, MATCH(AL11, {"Jan","Feb","Mar","Apr","May","Jun","Jul","Aug","Sep","Oct","Nov","Dec"},0), 1), 0)), "❌ Invalid", "✓ Valid")} -> ✓ Valid
T18: Dip Value | AL18: End Date | AO18: {=IF(AO9>DAY(EOMONTH(DATE(AO13, MATCH(AO11, {"Jan","Feb","Mar","Apr","May","Jun","Jul","Aug","Sep","Oct","Nov","Dec"},0), 1), 0)), "❌ Invalid", "✓ Valid")} -> ✓ Valid
O19: Opening Timestamp | T19: Opening | X19: Inflow | AA19: Outflow | AD19: Dip Change | AG19: Expected | AJ19: Variance
O20: =IFERROR(__xludf.DUMMYFUNCTION("iferror(min(filter(TSM!A:A,TSM!A:A>=AL15,TSM!A:A<AO15 + 1,TSM!D:D=""Tank 1"")),maxifs(TSM!A:A,TSM!D:D,""Tank 1""))"),45918.40860819444) -> 45918.409 | T20: =vlookup(O20,TSM!A:Q,8,FALSE) -> 2931 | X20: =SUMIFS(TSM!G:G,TSM!A:A,">=" & AL15,TSM!A:A, "<" & AO15 + 1,TSM!Q:Q,"Inflow",TSM!D:D,"Tank 1") -> 0 | AA20: =SUMIFS(TSM!G:G,TSM!A:A,">=" & AL15,TSM!A:A, "<" & AO15 + 1,TSM!Q:Q,"Outflow",TSM!D:D,"Tank 1") -> 0 | AD20: =SUMIFS(Sheet7!F:F,Sheet7!A:A,">=" & AL15,Sheet7!A:A, "<" & AO15 + 1) -> 0 | AG20: =T20+X20-AA20+AD20 -> 2931 | AJ20: =StockOverview!B5-AG20 -> -2931
O21: =IFERROR(__xludf.DUMMYFUNCTION("iferror(min(filter(TSM!A:A,TSM!A:A>=AL15,TSM!A:A<AO15 + 1,TSM!D:D=""Tank 2"")),maxifs(TSM!A:A,TSM!D:D,""Tank 2""))"),45919.067930798614) -> 45919.068 | T21: =vlookup(O21,TSM!A:Q,8,FALSE) -> 34179 | X21: =SUMIFS(TSM!G:G,TSM!A:A,">="&AL15,TSM!A:A, "<"&AO15 + 1,TSM!Q:Q,"Inflow",TSM!D:D,"Tank 2") -> 0 | AA21: =SUMIFS(TSM!G:G,TSM!A:A,">=" & AL15,TSM!A:A, "<" & AO15 + 1,TSM!Q:Q,"Outflow",TSM!D:D,"Tank 2") -> 0 | AD21: =SUMIFS(Sheet7!M:M,Sheet7!H:H,">=" & AL15,Sheet7!H:H, "<" & AO15 + 1) -> 0 | AG21: =T21+X21-AA21+AD21 -> 34179 | AJ21: =StockOverview!B6-AG21 -> -34179
O22: =IFERROR(__xludf.DUMMYFUNCTION("iferror(min(filter(TSM!A:A,TSM!A:A>=AL15,TSM!A:A<AO15 + 1,TSM!D:D=""Tank 3"")),maxifs(TSM!A:A,TSM!D:D,""Tank 3""))"),45919.36097150463) -> 45919.361 | T22: =vlookup(O22,TSM!A:Q,8,FALSE) -> 283732 | X22: =SUMIFS(TSM!G:G,TSM!A:A,">=" & AL15,TSM!A:A, "<" & AO15 + 1,TSM!Q:Q,"Inflow",TSM!D:D,"Tank 3") -> 0 | AA22: =SUMIFS(TSM!G:G,TSM!A:A,">=" & AL15,TSM!A:A, "<" & AO15 + 1,TSM!Q:Q,"Outflow",TSM!D:D,"Tank 3") -> 0 | AD22: =SUMIFS(Sheet7!T:T,Sheet7!O:O,">=" & AL15,Sheet7!O:O, "<" & AO15 + 1) -> 0 | AG22: =T22+X22-AA22+AD22 -> 283732 | AJ22: =StockOverview!B7-AG22 -> -15090

Sheet StockOverview
B1: CURRENT DATE & TIME | F1: CURRENT SHIFT CYCLE
B2: =TEXT(NOW(),"DD, MMMM YYYY HH:MM") -> 21, September 2025 14:07 | F2: =(IF(TIMEVALUE(NOW()) < TIME(8,0,0), TODAY()-1+TIME(8,0,0), TODAY()+TIME(8,0,0))) -> 45921.333 | G2: =F2+1 -> 45922.333
A3: CURRENT TANK OVERVIEW
A4: Tank ID | B4: Current Stock (L) | C4: Capacity (L) | D4: Available Capacity | E4: % Filled | G4: Tank ID | H4: Opening Stock | I4: Closing Stock
A5: Tank 1 | B5: =IFERROR(__xludf.DUMMYFUNCTION("IFERROR(VLOOKUP(MAX(FILTER(TSM!A:A,TSM!A:A>=F2,TSM!A:A<G2,TSM!D:D=G5)),TSM!A:Q,10,FALSE),VLOOKUP(MAXIFS(TSM!A:A,TSM!D:D,G5),TSM!A:Q,10,FALSE))"),0.0) -> 0 | C5: 1035347 | D5: =C5-B5 -> 1035347 | E5: =B5/C5 -> 0 | F5: =IFERROR(__xludf.DUMMYFUNCTION("IFERROR(MIN(FILTER(TSM!A:A,TSM!A:A>=F2,TSM!A:A<G2,TSM!D:D=G5)),""DATE NOT AVAILABLE"")"),"DATE NOT AVAILABLE") -> DATE NOT AVAILABLE | G5: Tank 1 | H5: =IFERROR(__xludf.DUMMYFUNCTION("IFERROR(VLOOKUP(MIN(FILTER(TSM!A:A,TSM!A:A>=F2,TSM!A:A<G2,TSM!D:D=G5)),TSM!A:Q,8,FALSE),VLOOKUP( MAXIFS(TSM!A:A,TSM!D:D,G5),TSM!A:Q,10,FALSE))"),0.0) -> 0 | I5: =IFERROR(__xludf.DUMMYFUNCTION("IFERROR(VLOOKUP(MAX(FILTER(TSM!A:A,TSM!A:A>=F2,TSM!A:A<G2,TSM!D:D=G5)),TSM!A:Q,10,FALSE),VLOOKUP(MAXIFS(TSM!A:A,TSM!D:D,G5),TSM!A:Q,10,FALSE))"),0.0) -> 0
A6: Tank 2 | B6: =IFERROR(__xludf.DUMMYFUNCTION("IFERROR(VLOOKUP(MAX(FILTER(TSM!A:A,TSM!A:A>=F2,TSM!A:A<G2,TSM!D:D=G6)),TSM!A:Q,10,FALSE),VLOOKUP(MAXIFS(TSM!A:A,TSM!D:D,G6),TSM!A:Q,10,FALSE))"),0.0) -> 0 | C6: 1112883 | D6: =C6-B6 -> 1112883 | E6: =B6/C6 -> 0 | F6: =IFERROR(__xludf.DUMMYFUNCTION("IFERROR(MIN(FILTER(TSM!A:A,TSM!A:A>=F2,TSM!A:A<G2,TSM!D:D=G6)),""DATE NOT AVAILABLE"")"),"DATE NOT AVAILABLE") -> DATE NOT AVAILABLE | G6: Tank 2 | H6: =IFERROR(__xludf.DUMMYFUNCTION("IFERROR(VLOOKUP(MIN(FILTER(TSM!A:A,TSM!A:A>=F2,TSM!A:A<G2,TSM!D:D=G6)),TSM!A:Q,8,FALSE),VLOOKUP(MAXIFS(TSM!A:A,TSM!D:D,G6),TSM!A:Q,10,FALSE))"),0.0) -> 0 | I6: =IFERROR(__xludf.DUMMYFUNCTION("IFERROR(VLOOKUP(MAX(FILTER(TSM!A:A,TSM!A:A>=F2,TSM!A:A<G2,TSM!D:D=G6)),TSM!A:Q,10,FALSE),VLOOKUP(MAXIFS(TSM!A:A,TSM!D:D,G6),TSM!A:Q,10,FALSE))"),0.0) -> 0
A7: Tank 3 | B7: =IFERROR(__xludf.DUMMYFUNCTION("IFERROR(VLOOKUP(MAX(FILTER(TSM!A:A,TSM!A:A>=F2,TSM!A:A<G2,TSM!D:D=G7)),TSM!A:Q,10,FALSE),VLOOKUP(MAXIFS(TSM!A:A,TSM!D:D,G7),TSM!A:Q,10,FALSE))"),268642.0) -> 268642 | C7: 1416494 | D7: =C7-B7 -> 1147852 | E7: =B7/C7 -> 0.18965276 | F7: =IFERROR(__xludf.DUMMYFUNCTION("IFERROR(MIN(FILTER(TSM!A:A,TSM!A:A>=F2,TSM!A:A<G2,TSM!D:D=G7)),""DATE NOT AVAILABLE"")"),"DATE NOT AVAILABLE") -> DATE NOT AVAILABLE | G7: Tank 3 | H7: =IFERROR(__xludf.DUMMYFUNCTION("IFERROR(VLOOKUP(MIN(FILTER(TSM!A:A,TSM!A:A>=F2,TSM!A:A<G2,TSM!D:D=G7)),TSM!A:Q,8,FALSE),VLOOKUP(MAXIFS(TSM!A:A,TSM!D:D,G7),TSM!A:Q,10,FALSE))"),268642.0) -> 268642 | I7: =IFERROR(__xludf.DUMMYFUNCTION("IFERROR(VLOOKUP(MAX(FILTER(TSM!A:A,TSM!A:A>=F2,TSM!A:A<G2,TSM!D:D=G7)),TSM!A:Q,10,FALSE),VLOOKUP(MAXIFS(TSM!A:A,TSM!D:D,G7),TSM!A:Q,10,FALSE))"),268642.0) -> 268642
A8: Total | B8: =SUM(B5:B7) -> 268642 | C8: =SUM(C5:C7) -> 3564724 | D8: =SUM(D5:D7) -> 3296082 | E8: =B8/C8 -> 0.075361234
G9: =IFERROR(__xludf.DUMMYFUNCTION("if(min(filter(TSM!A:A,TSM!A:A>=F2,TSM!A:A<G2)),vlookup(min(filter(TSM!A:A,TSM!A:A>=F2,TSM!A:A<G2)),TSM!A:Q,9,FALSE),"""")"),"#N/A") -> #N/A
A10: CURRENT BOWSER OVERVIEW
A11: Bowser ID | B11: Current Stock (L) | C11: Capacity (L) | F11: Total Inflow | H11: Total Outflow
A12: Adeyemi | B12: =IFERROR(VLOOKUP(MAXIFS(TSM!A:A,TSM!F:F,A12),TSM!A:Q,14,FALSE),"") -> 54596 | C12: 58000 | E12: Bowser ID | F12: Expected | G12: Actual | H12: Expected | I12: Actual
A13: Akachi | B13: =IFERROR(VLOOKUP(MAXIFS(TSM!A:A,TSM!F:F,A13),TSM!A:Q,14,FALSE),"") -> 35161 | C13: 37000 | E13: Adeyemi | F13: =SUMIFS(TSM!K:K,TSM!E:E,"Loading",TSM!F:F,E13,TSM!A:A,MAXIFS(TSM!A:A,TSM!A:A,TSM!A:A>=F2,TSM!A:A<G2,TSM!F:F,E13)) -> 0
A14: Ashake | B14: =IFERROR(VLOOKUP(MAXIFS(TSM!A:A,TSM!F:F,A14),TSM!A:Q,14,FALSE),"") -> 5493 | C14: 28000 | E14: Akachi | F14: =SUMIFS(TSM!K:K,TSM!E:E,"Loading",TSM!F:F,E14,TSM!A:A,MAXIFS(TSM!A:A,TSM!A:A,TSM!A:A>=F3,TSM!A:A<G3,TSM!F:F,E14)) -> 0
A15: Divine Grace | B15: =IFERROR(VLOOKUP(MAXIFS(TSM!A:A,TSM!F:F,A15),TSM!A:Q,14,FALSE),"") -> 54990 | C15: 58000 | E15: Ashake | F15: =SUMIFS(TSM!K:K,TSM!E:E,"Loading",TSM!F:F,E15,TSM!A:A,MAXIFS(TSM!A:A,TSM!A:A,TSM!A:A>=F4,TSM!A:A<G4,TSM!F:F,E15)) -> 0
A16: Odogwu | B16: =IFERROR(VLOOKUP(MAXIFS(TSM!A:A,TSM!F:F,A16),TSM!A:Q,14,FALSE),"") -> 41009 | C16: 40000 | E16: Divine Grace | F16: =SUMIFS(TSM!K:K,TSM!E:E,"Loading",TSM!F:F,E16,TSM!A:A,MAXIFS(TSM!A:A,TSM!A:A,TSM!A:A>=F5,TSM!A:A<G5,TSM!F:F,E16)) -> 0
A17: Roseline | B17: =IFERROR(VLOOKUP(MAXIFS(TSM!A:A,TSM!F:F,A17),TSM!A:Q,14,FALSE),"") | C17: 30000 | E17: Odogwu | F17: =SUMIFS(TSM!K:K,TSM!E:E,"Loading",TSM!F:F,E17,TSM!A:A,MAXIFS(TSM!A:A,TSM!A:A,TSM!A:A>=F6,TSM!A:A<G6,TSM!F:F,E17)) -> 0
A18: Seriki | B18: =IFERROR(VLOOKUP(MAXIFS(TSM!A:A,TSM!F:F,A18),TSM!A:Q,14,FALSE),"") -> 31086 | C18: 38000 | E18: Roseline | F18: =SUMIFS(TSM!K:K,TSM!E:E,"Loading",TSM!F:F,E18,TSM!A:A,MAXIFS(TSM!A:A,TSM!A:A,TSM!A:A>=F7,TSM!A:A<G7,TSM!F:F,E18)) -> 0
A19: Sultan | B19: =IFERROR(VLOOKUP(MAXIFS(TSM!A:A,TSM!F:F,A19),TSM!A:Q,14,FALSE),"") -> 55000 | C19: 57000 | E19: Seriki | F19: =SUMIFS(TSM!K:K,TSM!E:E,"Loading",TSM!F:F,E19,TSM!A:A,MAXIFS(TSM!A:A,TSM!A:A,TSM!A:A>=F8,TSM!A:A<G8,TSM!F:F,E19)) -> 0
A20: TOTAL | B20: =SUM(B12:B19) -> 277335 | E20: Sultan | F20: =SUMIFS(TSM!K:K,TSM!E:E,"Loading",TSM!F:F,E20,TSM!A:A,MAXIFS(TSM!A:A,TSM!A:A,TSM!A:A>=F9,TSM!A:A<G9,TSM!F:F,E20)) -> 0
E54: Today's Date:
E55: =TODAY() -> 45921

Sheet TSM
A1: Timestamp | B1: Date | C1: Month | D1: Tank ID | E1: Tank Activity | F1: Equipment ID | G1: Meter Reading | H1: Opening Stock | I1: Expected Stock | J1: Closing Stock | K1: Quantity | L1: Variance | M1: Bowser Opening Stock | N1: Bowser Closing Stock | O1: Quantity Received | P1: Operator | Q1: Movement Type
A2: 45903.446 | B2: 45903 | C2: =text(B2,"mmmm") -> September | D2: Tank 1 | E2: Loading | F2: Akachi | G2: 10318 | H2: 761882 | I2: =IF(E2="Loading",H2-G2,H2+G2) -> 751564 | J2: 751610 | K2: =abs(J2-H2) -> 10272 | L2: =J2-I2 -> 46 | O2: =N2-M2 -> 0 | P2: Seyi | Q2: =iferror(ifs(E:E="Loading","Outflow",or(E:E="Discharge", E:E= "Bowser Transfer"),"Inflow"), "No Data") -> Outflow
A3: 45903.663 | B3: 45903 | C3: =text(B3,"mmmm") -> September | D3: Tank 1 | E3: Loading | F3: Akachi | G3: 29545 | H3: 751610 | I3: =IF(E3="Loading",H3-G3,H3+G3) -> 722065 | J3: 722035 | K3: =abs(J3-H3) -> 29575 | L3: =J3-I3 -> -30 | O3: =N3-M3 -> 0 | P3: Chuks | Q3: =iferror(ifs(E:E="Loading","Outflow",or(E:E="Discharge", E:E= "Bowser Transfer"),"Inflow"), "No Data") -> Outflow
A4: 45903.678 | B4: 45903 | C4: =text(B4,"mmmm") -> September | D4: Tank 1 | E4: Loading | F4: Seriki | G4: 15350 | H4: 722035 | I4: =IF(E4="Loading",H4-G4,H4+G4) -> 706685 | J4: 706470 | K4: =abs(J4-H4) -> 15565 | L4: =J4-I4 -> -215 | O4: =N4-M4 -> 0 | P4: Seyi | Q4: =iferror(ifs(E:E="Loading","Outflow",or(E:E="Discharge", E:E= "Bowser Transfer"),"Inflow"), "No Data") -> Outflow
A5: 45904.197 | B5: 45904 | C5: =text(B5,"mmmm") -> September | D5: Tank 1 | E5: Loading | F5: Divine Grace | G5: 47990 | H5: 706470 | I5: =IF(E5="Loading",H5-G5,H5+G5) -> 658480 | J5: 657907 | K5: =abs(J5-H5) -> 48563 | L5: =J5-I5 -> -573 | O5: =N5-M5 -> 0 | P5: Chuks | Q5: =iferror(ifs(E:E="Loading","Outflow",or(E:E="Discharge", E:E= "Bowser Transfer"),"Inflow"), "No Data") -> Outflow
A6: 45904.413 | B6: 45904 | C6: =text(B6,"mmmm") -> September | D6: Tank 1 | E6: Loading | F6: Akachi | G6: 32081 | H6: 657907 | I6: =IF(E6="Loading",H6-G6,H6+G6) -> 625826 | J6: 625541 | K6: =abs(J6-H6) -> 32366 | L6: =J6-I6 -> -285 | O6: =N6-M6 -> 0 | P6: Seyi | Q6: =iferror(ifs(E:E="Loading","Outflow",or(E:E="Discharge", E:E= "Bowser Transfer"),"Inflow"), "No Data") -> Outflow
A7: 45904.426 | B7: 45904 | C7: =text(B7,"mmmm") -> September | D7: Tank 1 | E7: Loading | F7: Seriki | G7: 12500 | H7: 625541 | I7: =IF(E7="Loading",H7-G7,H7+G7) -> 613041 | J7: 613101 | K7: =abs(J7-H7) -> 12440 | L7: =J7-I7 -> 60 | O7: =N7-M7 -> 0 | P7: Seyi | Q7: =iferror(ifs(E:E="Loading","Outflow",or(E:E="Discharge", E:E= "Bowser Transfer"),"Inflow"), "No Data") -> Outflow
A8: 45904.488 | B8: 45903 | C8: =text(B8,"mmmm") -> September | D8: Tank 2 | E8: Loading | F8: Seriki | G8: 28620 | H8: 35325 | I8: =if(E8="Loading",H8-G8,H8+G8) -> 6705 | J8: 6664 | K8: =abs(J8-H8) -> 28661 | L8: =J8-I8 -> -41 | O8: =N8-M8 -> 0 | P8: Seyi | Q8: =iferror(ifs(E:E="Loading","Outflow",or(E:E="Discharge", E:E= "Bowser Transfer"),"Inflow"), "No Data") -> Outflow
A9: 45904.493 | B9: 45903 | C9: =text(B9,"mmmm") -> September | D9: Tank 2 | E9: Loading | F9: Akachi | G9: 6758 | H9: 6664 | I9: =if(E9="Loading",H9-G9,H9+G9) -> -94 | J9: 0 | K9: =abs(J9-H9) -> 6664 | L9: =J9-I9 -> 94 | O9: =N9-M9 -> 0 | P9: Seyi | Q9: =iferror(ifs(E:E="Loading","Outflow",or(E:E="Discharge", E:E= "Bowser Transfer"),"Inflow"), "No Data") -> Outflow
A10: 45904.652 | B10: 45904 | C10: =text(B10,"mmmm") -> September | D10: Tank 1 | E10: Loading | F10: Akachi | G10: 28321 | H10: 613101 | I10: =IF(E10="Loading",H10-G10,H10+G10) -> 584780 | J10: 584073 | K10: =abs(J10-H10) -> 29028 | L10: =J10-I10 -> -707 | O10: =N10-M10 -> 0 | P10: Seyi | Q10: =iferror(ifs(E:E="Loading","Outflow",or(E:E="Discharge", E:E= "Bowser Transfer"),"Inflow"), "No Data") -> Outflow
A11: 45905.953 | B11: 45905 | C11: =text(B11,"mmmm") -> September | D11: Tank 2 | E11: Discharge | F11: T15326LA | G11: 44910 | H11: 0 | I11: =if(E11="Loading",H11-G11,H11+G11) -> 44910 | J11: 45409 | K11: =abs(J11-H11) -> 45409 | L11: =J11-I11 -> 499 | O11: =N11-M11 -> 0 | P11: John | Q11: =iferror(ifs(E:E="Loading","Outflow",or(E:E="Discharge", E:E= "Bowser Transfer"),"Inflow"), "No Data") -> Inflow
A12: 45905.954 | B12: 45905 | C12: =text(B12,"mmmm") -> September | D12: Tank 2 | E12: Discharge | F12: T15327LA | G12: 44900 | H12: 45409 | I12: =if(E12="Loading",H12-G12,H12+G12) -> 90309 | J12: 90844 | K12: =abs(J12-H12) -> 45435 | L12: =J12-I12 -> 535 | O12: =N12-M12 -> 0 | P12: Jamiu | Q12: =iferror(ifs(E:E="Loading","Outflow",or(E:E="Discharge", E:E= "Bowser Transfer"),"Inflow"), "No Data") -> Inflow
A13: 45905.955 | B13: 45905 | C13: =text(B13,"mmmm") -> September | D13: Tank 2 | E13: Discharge | F13: T20463LA | G13: 39930 | H13: 90844 | I13: =if(E13="Loading",H13-G13,H13+G13) -> 130774 | J13: 130189 | K13: =abs(J13-H13) -> 39345 | L13: =J13-I13 -> -585 | O13: =N13-M13 -> 0 | P13: Jamiu | Q13: =iferror(ifs(E:E="Loading","Outflow",or(E:E="Discharge", E:E= "Bowser Transfer"),"Inflow"), "No Data") -> Inflow
A14: 45905.956 | B14: 45905 | C14: =text(B14,"mmmm") -> September | D14: Tank 2 | E14: Discharge | F14: ABC784XD | G14: 44880 | H14: 130189 | I14: =if(E14="Loading",H14-G14,H14+G14) -> 175069 | J14: 175612 | K14: =abs(J14-H14) -> 45423 | L14: =J14-I14 -> 543 | O14: =N14-M14 -> 0 | P14: Seyi | Q14: =iferror(ifs(E:E="Loading","Outflow",or(E:E="Discharge", E:E= "Bowser Transfer"),"Inflow"), "No Data") -> Inflow
A15: 45905.957 | B15: 45905 | C15: =text(B15,"mmmm") -> September | D15: Tank 2 | E15: Discharge | F15: T19344LA | G15: 44930 | H15: 175612 | I15: =if(E15="Loading",H15-G15,H15+G15) -> 220542 | J15: 220628 | K15: =abs(J15-H15) -> 45016 | L15: =J15-I15 -> 86 | O15: =N15-M15 -> 0 | P15: Seyi | Q15: =iferror(ifs(E:E="Loading","Outflow",or(E:E="Discharge", E:E= "Bowser Transfer"),"Inflow"), "No Data") -> Inflow
A16: 45905.959 | B16: 45905 | C16: =text(B16,"mmmm") -> September | D16: Tank 2 | E16: Discharge | F16: T19390LA | G16: 44910 | H16: 220628 | I16: =if(E16="Loading",H16-G16,H16+G16) -> 265538 | J16: 265540 | K16: =abs(J16-H16) -> 44912 | L16: =J16-I16 -> 2 | O16: =N16-M16 -> 0 | P16: Chuks | Q16: =iferror(ifs(E:E="Loading","Outflow",or(E:E="Discharge", E:E= "Bowser Transfer"),"Inflow"), "No Data") -> Inflow
A17: 45905.982 | B17: 45905 | C17: =text(B17,"mmmm") -> September | D17: Tank 2 | E17: Discharge | F17: T15325LA | G17: 44900 | H17: 265540 | I17: =if(E17="Loading",H17-G17,H17+G17) -> 310440 | J17: 310349 | K17: =abs(J17-H17) -> 44809 | L17: =J17-I17 -> -91 | O17: =N17-M17 -> 0 | P17: Chuks | Q17: =iferror(ifs(E:E="Loading","Outflow",or(E:E="Discharge", E:E= "Bowser Transfer"),"Inflow"), "No Data") -> Inflow
A18: 45906.035 | B18: 45905 | C18: =text(B18,"mmmm") -> September | D18: Tank 2 | E18: Discharge | F18: T19345LA | G18: 44900 | H18: 310349 | I18: =if(E18="Loading",H18-G18,H18+G18) -> 355249 | J18: 354961 | K18: =abs(J18-H18) -> 44612 | L18: =J18-I18 -> -288 | O18: =N18-M18 -> 0 | P18: Chuks | Q18: =iferror(ifs(E:E="Loading","Outflow",or(E:E="Discharge", E:E= "Bowser Transfer"),"Inflow"), "No Data") -> Inflow
A19: 45906.122 | B19: 45905 | C19: =text(B19,"mmmm") -> September | D19: Tank 2 | E19: Discharge | F19: KMC128ZQ | G19: 44900 | H19: 354961 | I19: =if(E19="Loading",H19-G19,H19+G19) -> 399861 | J19: 400097 | K19: =abs(J19-H19) -> 45136 | L19: =J19-I19 -> 236 | O19: =N19-M19 -> 0 | P19: Chuks | Q19: =iferror(ifs(E:E="Loading","Outflow",or(E:E="Discharge", E:E= "Bowser Transfer"),"Inflow"), "No Data") -> Inflow
A20: 45906.153 | B20: 45905 | C20: =text(B20,"mmmm") -> September | D20: Tank 1 | E20: Loading | F20: Akachi | G20: 26524 | H20: 581896 | I20: =IF(E20="Loading",H20-G20,H20+G20) -> 555372 | J20: 555150 | K20: =abs(J20-H20) -> 26746 | L20: =J20-I20 -> -222 | O20: =N20-M20 -> 0 | P20: John | Q20: =iferror(ifs(E:E="Loading","Outflow",or(E:E="Discharge", E:E= "Bowser Transfer"),"Inflow"), "No Data") -> Outflow
A21: 45906.154 | B21: 45905 | C21: =text(B21,"mmmm") -> September | D21: Tank 1 | E21: Loading | F21: Seriki | G21: 14120 | H21: 555150 | I21: =IF(E21="Loading",H21-G21,H21+G21) -> 541030 | J21: 541880 | K21: =abs(J21-H21) -> 13270 | L21: =J21-I21 -> 850 | O21: =N21-M21 -> 0 | P21: John | Q21: =iferror(ifs(E:E="Loading","Outflow",or(E:E="Discharge", E:E= "Bowser Transfer"),"Inflow"), "No Data") -> Outflow
A22: 45906.155 | B22: 45905 | C22: =text(B22,"mmmm") -> September | D22: Tank 1 | E22: Loading | F22: Akachi | G22: 32618 | H22: 541880 | I22: =IF(E22="Loading",H22-G22,H22+G22) -> 509262 | J22: 509224 | K22: =abs(J22-H22) -> 32656 | L22: =J22-I22 -> -38 | O22: =N22-M22 -> 0 | P22: John | Q22: =iferror(ifs(E:E="Loading","Outflow",or(E:E="Discharge", E:E= "Bowser Transfer"),"Inflow"), "No Data") -> Outflow
A23: 45906.156 | B23: 45905 | C23: =text(B23,"mmmm") -> September | D23: Tank 1 | E23: Loading | F23: Seriki | G23: 29540 | H23: 509224 | I23: =IF(E23="Loading",H23-G23,H23+G23) -> 479684 | J23: 479367 | K23: =abs(J23-H23) -> 29857 | L23: =J23-I23 -> -317 | O23: =N23-M23 -> 0 | P23: Chuks | Q23: =iferror(ifs(E:E="Loading","Outflow",or(E:E="Discharge", E:E= "Bowser Transfer"),"Inflow"), "No Data") -> Outflow
A24: 45906.831 | B24: 45906 | C24: =text(B24,"mmmm") -> September | D24: Tank 1 | E24: Loading | F24: Akachi | G24: 26016 | H24: 479367 | I24: =IF(E24="Loading",H24-G24,H24+G24) -> 453351 | J24: 453359 | K24: =abs(J24-H24) -> 26008 | L24: =J24-I24 -> 8 | O24: =N24-M24 -> 0 | P24: Jamiu | Q24: =iferror(ifs(E:E="Loading","Outflow",or(E:E="Discharge", E:E= "Bowser Transfer"),"Inflow"), "No Data") -> Outflow
A25: 45906.832 | B25: 45906 | C25: =text(B25,"mmmm") -> September | D25: Tank 1 | E25: Loading | F25: Seriki | G25: 18010 | H25: 453359 | I25: =IF(E25="Loading",H25-G25,H25+G25) -> 435349 | J25: 435537 | K25: =abs(J25-H25) -> 17822 | L25: =J25-I25 -> 188 | O25: =N25-M25 -> 0 | P25: Jamiu | Q25: =iferror(ifs(E:E="Loading","Outflow",or(E:E="Discharge", E:E= "Bowser Transfer"),"Inflow"), "No Data") -> Outflow
A26: 45906.983 | B26: 45906 | C26: =text(B26,"mmmm") -> September | D26: Tank 2 | E26: Discharge | F26: FKJ21XJ | G26: 44840 | H26: 445440 | I26: =if(E26="Loading",H26-G26,H26+G26) -> 490280 | J26: 489547 | K26: =abs(J26-H26) -> 44107 | L26: =J26-I26 -> -733 | O26: =N26-M26 -> 0 | P26: Jamiu | Q26: =iferror(ifs(E:E="Loading","Outflow",or(E:E="Discharge", E:E= "Bowser Transfer"),"Inflow"), "No Data") -> Inflow
A27: 45906.987 | B27: 45906 | C27: =text(B27,"mmmm") -> September | D27: Tank 2 | E27: Discharge | F27: KAF75XE | G27: 44710 | H27: 489547 | I27: =if(E27="Loading",H27-G27,H27+G27) -> 534257 | J27: 534353 | K27: =abs(J27-H27) -> 44806 | L27: =J27-I27 -> 96 | O27: =N27-M27 -> 0 | P27: Jamiu | Q27: =iferror(ifs(E:E="Loading","Outflow",or(E:E="Discharge", E:E= "Bowser Transfer"),"Inflow"), "No Data") -> Inflow
A28: 45906.988 | B28: 45906 | C28: =text(B28,"mmmm") -> September | D28: Tank 2 | E28: Discharge | F28: T20959LA | G28: 44830 | H28: 534353 | I28: =if(E28="Loading",H28-G28,H28+G28) -> 579183 | J28: 579603 | K28: =abs(J28-H28) -> 45250 | L28: =J28-I28 -> 420 | O28: =N28-M28 -> 0 | P28: Jamiu | Q28: =iferror(ifs(E:E="Loading","Outflow",or(E:E="Discharge", E:E= "Bowser Transfer"),"Inflow"), "No Data") -> Inflow
A29: 45906.989 | B29: 45906 | C29: =text(B29,"mmmm") -> September | D29: Tank 1 | E29: Discharge | F29: T6707LA | G29: 39900 | H29: 435537 | I29: =if(E29="Loading",H29-G29,H29+G29) -> 475437 | J29: 475741 | K29: =abs(J29-H29) -> 40204 | L29: =J29-I29 -> 304 | O29: =N29-M29 -> 0 | P29: Jamiu | Q29: =iferror(ifs(E:E="Loading","Outflow",or(E:E="Discharge", E:E= "Bowser Transfer"),"Inflow"), "No Data") -> Inflow
A30: 45907.173 | B30: 45906 | C30: =text(B30,"mmmm") -> September | D30: Tank 1 | E30: Discharge | F30: T15327LA | G30: 44850 | H30: 475741 | I30: =if(E30="Loading",H30-G30,H30+G30) -> 520591 | J30: 519902 | K30: =abs(J30-H30) -> 44161 | L30: =J30-I30 -> -689 | O30: =N30-M30 -> 0 | P30: Chuks | Q30: =iferror(ifs(E:E="Loading","Outflow",or(E:E="Discharge", E:E= "Bowser Transfer"),"Inflow"), "No Data") -> Inflow
A31: 45907.174 | B31: 45906 | C31: =text(B31,"mmmm") -> September | D31: Tank 1 | E31: Discharge | F31: FKJ21XJ | G31: 44900 | H31: 519902 | I31: =if(E31="Loading",H31-G31,H31+G31) -> 564802 | J31: 564583 | K31: =abs(J31-H31) -> 44681 | L31: =J31-I31 -> -219 | O31: =N31-M31 -> 0 | P31: Seyi | Q31: =iferror(ifs(E:E="Loading","Outflow",or(E:E="Discharge", E:E= "Bowser Transfer"),"Inflow"), "No Data") -> Inflow
A32: 45907.217 | B32: 45906 | C32: =text(B32,"mmmm") -> September | D32: Tank 1 | E32: Discharge | F32: T15326LA | G32: 44910 | H32: 564583 | I32: =if(E32="Loading",H32-G32,H32+G32) -> 609493 | J32: 609473 | K32: =abs(J32-H32) -> 44890 | L32: =J32-I32 -> -20 | O32: =N32-M32 -> 0 | P32: Chuks | Q32: =iferror(ifs(E:E="Loading","Outflow",or(E:E="Discharge", E:E= "Bowser Transfer"),"Inflow"), "No Data") -> Inflow
A33: 45909.909 | B33: 45907 | C33: =text(B33,"mmmm") -> September | D33: Tank 1 | E33: Discharge | F33: T19345LA | G33: 40890 | H33: 609473 | I33: =if(E33="Loading",H33-G33,H33+G33) -> 650363 | J33: 650435 | K33: =abs(J33-H33) -> 40962 | L33: =J33-I33 -> 72 | O33: =N33-M33 -> 0 | P33: Bode | Q33: =iferror(ifs(E:E="Loading","Outflow",or(E:E="Discharge", E:E= "Bowser Transfer"),"Inflow"), "No Data") -> Inflow
A34: 45909.912 | B34: 45907 | C34: =text(B34,"mmmm") -> September | D34: Tank 1 | E34: Loading | F34: Seriki | G34: 13560 | H34: 650435 | I34: =if(E34="Loading",H34-G34,H34+G34) -> 636875 | J34: 636634 | K34: =abs(J34-H34) -> 13801 | L34: =J34-I34 -> -241 | O34: =N34-M34 -> 0 | P34: Bode | Q34: =iferror(ifs(E:E="Loading","Outflow",or(E:E="Discharge", E:E= "Bowser Transfer"),"Inflow"), "No Data") -> Outflow
A35: 45909.916 | B35: 45907 | C35: =text(B35,"mmmm") -> September | D35: Tank 1 | E35: Loading | F35: Akachi | G35: 31019 | H35: 636634 | I35: =if(E35="Loading",H35-G35,H35+G35) -> 605615 | J35: 605637 | K35: =abs(J35-H35) -> 30997 | L35: =J35-I35 -> 22 | O35: =N35-M35 -> 0 | P35: Bode | Q35: =iferror(ifs(E:E="Loading","Outflow",or(E:E="Discharge", E:E= "Bowser Transfer"),"Inflow"), "No Data") -> Outflow
A36: 45909.918 | B36: 45907 | C36: =text(B36,"mmmm") -> September | D36: Tank 1 | E36: Loading | F36: Akachi | G36: 31012 | H36: 605637 | I36: =if(E36="Loading",H36-G36,H36+G36) -> 574625 | J36: 574639 | K36: =abs(J36-H36) -> 30998 | L36: =J36-I36 -> 14 | O36: =N36-M36 -> 0 | P36: Bode | Q36: =iferror(ifs(E:E="Loading","Outflow",or(E:E="Discharge", E:E= "Bowser Transfer"),"Inflow"), "No Data") -> Outflow
A37: 45909.919 | B37: 45907 | C37: =text(B37,"mmmm") -> September | D37: Tank 1 | E37: Loading | F37: Seriki | G37: 12070 | H37: 574639 | I37: =if(E37="Loading",H37-G37,H37+G37) -> 562569 | J37: 562614 | K37: =abs(J37-H37) -> 12025 | L37: =J37-I37 -> 45 | O37: =N37-M37 -> 0 | P37: John | Q37: =iferror(ifs(E:E="Loading","Outflow",or(E:E="Discharge", E:E= "Bowser Transfer"),"Inflow"), "No Data") -> Outflow
... A45: 45910.666 | B45: 45908 | C45: =text(B45,"mmmm") -> September | D45: Tank 2 | E45: Loading | F45: Sultan | G45: 52880 | H45: 461523 | I45: =if(E45="Loading",H45-G45,H45+G45) -> 408643 | J45: 408294 | K45: =abs(J45-H45) -> 53229 | L45: =J45-I45 -> -349 | O45: =N45-M45 -> 0 | P45: John | Q45: =iferror(ifs(E:E="Loading","Outflow",or(E:E="Discharge", E:E= "Bowser Transfer"),"Inflow"), "No Data") -> Outflow
A46: 45910.667 | B46: 45908 | C46: =text(B46,"mmmm") -> September | D46: Tank 2 | E46: Loading | F46: Odogwu | G46: 39560 | H46: 408294 | I46: =if(E46="Loading",H46-G46,H46+G46) -> 368734 | J46: 368657 | K46: =abs(J46-H46) -> 39637 | L46: =J46-I46 -> -77 | M46: 1114 | N46: 41009 | O46: =N46-M46 -> 39895 | P46: John | Q46: =iferror(ifs(E:E="Loading","Outflow",or(E:E="Discharge", E:E= "Bowser Transfer"),"Inflow"), "No Data") -> Outflow
A47: 45910.67 | B47: 45908 | C47: =text(B47,"mmmm") -> September | D47: Tank 2 | E47: Loading | F47: Sultan | G47: 54240 | H47: 368657 | I47: =if(E47="Loading",H47-G47,H47+G47) -> 314417 | J47: 314498 | K47: =abs(J47-H47) -> 54159 | L47: =J47-I47 -> 81 | O47: =N47-M47 -> 0 | P47: John | Q47: =iferror(ifs(E:E="Loading","Outflow",or(E:E="Discharge", E:E= "Bowser Transfer"),"Inflow"), "No Data") -> Outflow
...

Sheet Sheet7
A1: TANK 1 | H1: TANK 2 | O1: TANK 3
A2: Timestamp | B2: Date | C2: Opening | D2: Closing | E2: Chronological | F2: Difference | H2: Timestamp | I2: Date | J2: Opening | K2: Closing | L2: Chronological | M2: Difference | O2: Timestamp | P2: Date | Q2: Opening | R2: Closing | S2: Chronological | T2: Difference
A3: =IFERROR(__xludf.DUMMYFUNCTION("FILTER(TSM!A:A,TSM!D:D=""Tank 1"")"),45903.44634259259) -> 45903.446 | B3: =IFERROR(vlookup(A3,TSM!A:Q,2,FALSE),"") -> 45903 | C3: =IFERROR(vlookup(A3,TSM!A:Q,8,FALSE),"") -> 761882 | D3: =IFERROR(vlookup(A3,TSM!A:Q,10,FALSE),"") -> 751610 | E3: =IF(D3=C4,"Yes","No") -> Yes | H3: =IFERROR(__xludf.DUMMYFUNCTION("FILTER(TSM!A:A,TSM!D:D=""Tank 2"")"),45904.48778946759) -> 45904.488 | I3: =IFERROR(vlookup(H3,TSM!A:Q,2,FALSE),"") -> 45903 | J3: =IFERROR(vlookup(H3,TSM!A:Q,8,FALSE),"") -> 35325 | K3: =IFERROR(vlookup(H3,TSM!A:Q,10,FALSE),"") -> 6664 | O3: =IFERROR(__xludf.DUMMYFUNCTION("FILTER(TSM!A:A,TSM!D:D=""Tank 3"")"),45918.44073945602) -> 45918.441 | P3: =IFERROR(vlookup(O3,TSM!A:Q,2,FALSE),"") -> 45915 | Q3: =IFERROR(vlookup(O3,TSM!A:Q,8,FALSE),"") -> 632469 | R3: =IFERROR(vlookup(O3,TSM!A:Q,10,FALSE),"") -> 608057
A4: =IFERROR(__xludf.DUMMYFUNCTION("""COMPUTED_VALUE"""),45903.663402777776) -> 45903.663 | B4: =IFERROR(vlookup(A4,TSM!A:Q,2,FALSE),"") -> 45903 | C4: =IFERROR(vlookup(A4,TSM!A:Q,8,FALSE),"") -> 751610 | D4: =IFERROR(vlookup(A4,TSM!A:Q,10,FALSE),"") -> 722035 | E4: =IF(D3=C4,"Yes","No") -> Yes | F4: =C4-D3 -> 0 | H4: =IFERROR(__xludf.DUMMYFUNCTION("""COMPUTED_VALUE"""),45904.49286761574) -> 45904.493 | I4: =IFERROR(vlookup(H4,TSM!A:Q,2,FALSE),"") -> 45903 | J4: =IFERROR(vlookup(H4,TSM!A:Q,8,FALSE),"") -> 6664 | K4: =IFERROR(vlookup(H4,TSM!A:Q,10,FALSE),"") -> 0 | L4: =IF(K3=J4,"Yes","No") -> Yes | M4: =J4-K3 -> 0 | O4: =IFERROR(__xludf.DUMMYFUNCTION("""COMPUTED_VALUE"""),45918.444725520836) -> 45918.445 | P4: =IFERROR(vlookup(O4,TSM!A:Q,2,FALSE),"") -> 45915 | Q4: =IFERROR(vlookup(O4,TSM!A:Q,8,FALSE),"") -> 608057 | R4: =IFERROR(vlookup(O4,TSM!A:Q,10,FALSE),"") -> 568130 | S4: =IF(R3=Q4,"Yes","No") -> Yes | T4: =R3-Q4 -> 0
A5: =IFERROR(__xludf.DUMMYFUNCTION("""COMPUTED_VALUE"""),45903.67787037037) -> 45903.678 | B5: =IFERROR(vlookup(A5,TSM!A:Q,2,FALSE),"") -> 45903 | C5: =IFERROR(vlookup(A5,TSM!A:Q,8,FALSE),"") -> 722035 | D5: =IFERROR(vlookup(A5,TSM!A:Q,10,FALSE),"") -> 706470 | E5: =IF(D4=C5,"Yes","No") -> Yes | F5: =C5-D4 -> 0 | H5: =IFERROR(__xludf.DUMMYFUNCTION("""COMPUTED_VALUE"""),45905.95327612269) -> 45905.953 | I5: =IFERROR(vlookup(H5,TSM!A:Q,2,FALSE),"") -> 45905 | J5: =IFERROR(vlookup(H5,TSM!A:Q,8,FALSE),"") -> 0 | K5: =IFERROR(vlookup(H5,TSM!A:Q,10,FALSE),"") -> 45409 | L5: =IF(K4=J5,"Yes","No") -> Yes | M5: =J5-K4 -> 0 | O5: =IFERROR(__xludf.DUMMYFUNCTION("""COMPUTED_VALUE"""),45918.44706958333) -> 45918.447 | P5: =IFERROR(vlookup(O5,TSM!A:Q,2,FALSE),"") -> 45915 | Q5: =IFERROR(vlookup(O5,TSM!A:Q,8,FALSE),"") -> 568130 | R5: =IFERROR(vlookup(O5,TSM!A:Q,10,FALSE),"") -> 552097 | S5: =IF(R4=Q5,"Yes","No") -> Yes | T5: =R4-Q5 -> 0
A6: =IFERROR(__xludf.DUMMYFUNCTION("""COMPUTED_VALUE"""),45904.197430555556) -> 45904.197 | B6: =IFERROR(vlookup(A6,TSM!A:Q,2,FALSE),"") -> 45904 | C6: =IFERROR(vlookup(A6,TSM!A:Q,8,FALSE),"") -> 706470 | D6: =IFERROR(vlookup(A6,TSM!A:Q,10,FALSE),"") -> 657907 | E6: =IF(D5=C6,"Yes","No") -> Yes | F6: =C6-D5 -> 0 | H6: =IFERROR(__xludf.DUMMYFUNCTION("""COMPUTED_VALUE"""),45905.95424071759) -> 45905.954 | I6: =IFERROR(vlookup(H6,TSM!A:Q,2,FALSE),"") -> 45905 | J6: =IFERROR(vlookup(H6,TSM!A:Q,8,FALSE),"") -> 45409 | K6: =IFERROR(vlookup(H6,TSM!A:Q,10,FALSE),"") -> 90844 | L6: =IF(K5=J6,"Yes","No") -> Yes | M6: =J6-K5 -> 0 | O6: =IFERROR(__xludf.DUMMYFUNCTION("""COMPUTED_VALUE"""),45918.839330312505) -> 45918.839 | P6: =IFERROR(vlookup(O6,TSM!A:Q,2,FALSE),"") -> 45916 | Q6: =IFERROR(vlookup(O6,TSM!A:Q,8,FALSE),"") -> 552097 | R6: =IFERROR(vlookup(O6,TSM!A:Q,10,FALSE),"") -> 531823 | S6: =IF(R5=Q6,"Yes","No") -> Yes | T6: =R5-Q6 -> 0
A7: =IFERROR(__xludf.DUMMYFUNCTION("""COMPUTED_VALUE"""),45904.41326388889) -> 45904.413 | B7: =IFERROR(vlookup(A7,TSM!A:Q,2,FALSE),"") -> 45904 | C7: =IFERROR(vlookup(A7,TSM!A:Q,8,FALSE),"") -> 657907 | D7: =IFERROR(vlookup(A7,TSM!A:Q,10,FALSE),"") -> 625541 | E7: =IF(D6=C7,"Yes","No") -> Yes | F7: =C7-D6 -> 0 | H7: =IFERROR(__xludf.DUMMYFUNCTION("""COMPUTED_VALUE"""),45905.95512831019) -> 45905.955 | I7: =IFERROR(vlookup(H7,TSM!A:Q,2,FALSE),"") -> 45905 | J7: =IFERROR(vlookup(H7,TSM!A:Q,8,FALSE),"") -> 90844 | K7: =IFERROR(vlookup(H7,TSM!A:Q,10,FALSE),"") -> 130189 | L7: =IF(K6=J7,"Yes","No") -> Yes | M7: =J7-K6 -> 0 | O7: =IFERROR(__xludf.DUMMYFUNCTION("""COMPUTED_VALUE"""),45918.84036502315) -> 45918.84 | P7: =IFERROR(vlookup(O7,TSM!A:Q,2,FALSE),"") -> 45916 | Q7: =IFERROR(vlookup(O7,TSM!A:Q,8,FALSE),"") -> 531823 | R7: =IFERROR(vlookup(O7,TSM!A:Q,10,FALSE),"") -> 499551 | S7: =IF(R6=Q7,"Yes","No") -> Yes | T7: =R6-Q7 -> 0
A8: =IFERROR(__xludf.DUMMYFUNCTION("""COMPUTED_VALUE"""),45904.425833333335) -> 45904.426 | B8: =IFERROR(vlookup(A8,TSM!A:Q,2,FALSE),"") -> 45904 | C8: =IFERROR(vlookup(A8,TSM!A:Q,8,FALSE),"") -> 625541 | D8: =IFERROR(vlookup(A8,TSM!A:Q,10,FALSE),"") -> 613101 | E8: =IF(D7=C8,"Yes","No") -> Yes | F8: =C8-D7 -> 0 | H8: =IFERROR(__xludf.DUMMYFUNCTION("""COMPUTED_VALUE"""),45905.95604160879) -> 45905.956 | I8: =IFERROR(vlookup(H8,TSM!A:Q,2,FALSE),"") -> 45905 | J8: =IFERROR(vlookup(H8,TSM!A:Q,8,FALSE),"") -> 130189 | K8: =IFERROR(vlookup(H8,TSM!A:Q,10,FALSE),"") -> 175612 | L8: =IF(K7=J8,"Yes","No") -> Yes | M8: =J8-K7 -> 0 | O8: =IFERROR(__xludf.DUMMYFUNCTION("""COMPUTED_VALUE"""),45918.84264454861) -> 45918.843 | P8: =IFERROR(vlookup(O8,TSM!A:Q,2,FALSE),"") -> 45916 | Q8: =IFERROR(vlookup(O8,TSM!A:Q,8,FALSE),"") -> 499551 | R8: =IFERROR(vlookup(O8,TSM!A:Q,10,FALSE),"") -> 479484 | S8: =IF(R7=Q8,"Yes","No") -> Yes | T8: =R7-Q8 -> 0
A9: =IFERROR(__xludf.DUMMYFUNCTION("""COMPUTED_VALUE"""),45904.65219907407) -> 45904.652 | B9: =IFERROR(vlookup(A9,TSM!A:Q,2,FALSE),"") -> 45904 | C9: =IFERROR(vlookup(A9,TSM!A:Q,8,FALSE),"") -> 613101 | D9: =IFERROR(vlookup(A9,TSM!A:Q,10,FALSE),"") -> 584073 | E9: =IF(D8=C9,"Yes","No") -> Yes | F9: =C9-D8 -> 0 | H9: =IFERROR(__xludf.DUMMYFUNCTION("""COMPUTED_VALUE"""),45905.95708886574) -> 45905.957 | I9: =IFERROR(vlookup(H9,TSM!A:Q,2,FALSE),"") -> 45905 | J9: =IFERROR(vlookup(H9,TSM!A:Q,8,FALSE),"") -> 175612 | K9: =IFERROR(vlookup(H9,TSM!A:Q,10,FALSE),"") -> 220628 | L9: =IF(K8=J9,"Yes","No") -> Yes | M9: =J9-K8 -> 0 | O9: =IFERROR(__xludf.DUMMYFUNCTION("""COMPUTED_VALUE"""),45918.845045821756) -> 45918.845 | P9: =IFERROR(vlookup(O9,TSM!A:Q,2,FALSE),"") -> 45916 | Q9: =IFERROR(vlookup(O9,TSM!A:Q,8,FALSE),"") -> 479484 | R9: =IFERROR(vlookup(O9,TSM!A:Q,10,FALSE),"") -> 447856 | S9: =IF(R8=Q9,"Yes","No") -> Yes | T9: =R8-Q9 -> 0
A10: =IFERROR(__xludf.DUMMYFUNCTION("""COMPUTED_VALUE"""),45906.15311564815) -> 45906.153 | B10: =IFERROR(vlookup(A10,TSM!A:Q,2,FALSE),"") -> 45905 | C10: =IFERROR(vlookup(A10,TSM!A:Q,8,FALSE),"") -> 581896 | D10: =IFERROR(vlookup(A10,TSM!A:Q,10,FALSE),"") -> 555150 | E10: =IF(D9=C10,"Yes","No") -> No | F10: =C10-D9 -> -2177 | H10: =IFERROR(__xludf.DUMMYFUNCTION("""COMPUTED_VALUE"""),45905.958537557875) -> 45905.959 | I10: =IFERROR(vlookup(H10,TSM!A:Q,2,FALSE),"") -> 45905 | J10: =IFERROR(vlookup(H10,TSM!A:Q,8,FALSE),"") -> 220628 | K10: =IFERROR(vlookup(H10,TSM!A:Q,10,FALSE),"") -> 265540 | L10: =IF(K9=J10,"Yes","No") -> Yes | M10: =J10-K9 -> 0 | O10: =IFERROR(__xludf.DUMMYFUNCTION("""COMPUTED_VALUE"""),45918.850174861116) -> 45918.85 | P10: =IFERROR(vlookup(O10,TSM!A:Q,2,FALSE),"") -> 45916 | Q10: =IFERROR(vlookup(O10,TSM!A:Q,8,FALSE),"") -> 447856 | R10: =IFERROR(vlookup(O10,TSM!A:Q,10,FALSE),"") -> 420882 | S10: =IF(R9=Q10,"Yes","No") -> Yes | T10: =R9-Q10 -> 0
A11: =IFERROR(__xludf.DUMMYFUNCTION("""COMPUTED_VALUE"""),45906.15418841435) -> 45906.154 | B11: =IFERROR(vlookup(A11,TSM!A:Q,2,FALSE),"") -> 45905 | C11: =IFERROR(vlookup(A11,TSM!A:Q,8,FALSE),"") -> 555150 | D11: =IFERROR(vlookup(A11,TSM!A:Q,10,FALSE),"") -> 541880 | E11: =IF(D10=C11,"Yes","No") -> Yes | F11: =C11-D10 -> 0 | H11: =IFERROR(__xludf.DUMMYFUNCTION("""COMPUTED_VALUE"""),45905.98246857639) -> 45905.982 | I11: =IFERROR(vlookup(H11,TSM!A:Q,2,FALSE),"") -> 45905 | J11: =IFERROR(vlookup(H11,TSM!A:Q,8,FALSE),"") -> 265540 | K11: =IFERROR(vlookup(H11,TSM!A:Q,10,FALSE),"") -> 310349 | L11: =IF(K10=J11,"Yes","No") -> Yes | M11: =J11-K10 -> 0 | O11: =IFERROR(__xludf.DUMMYFUNCTION("""COMPUTED_VALUE"""),45918.852054745366) -> 45918.852 | P11: =IFERROR(vlookup(O11,TSM!A:Q,2,FALSE),"") -> 45916 | Q11: =IFERROR(vlookup(O11,TSM!A:Q,8,FALSE),"") -> 420882 | R11: =IFERROR(vlookup(O11,TSM!A:Q,10,FALSE),"") -> 403415 | S11: =IF(R10=Q11,"Yes","No") -> Yes | T11: =R10-Q11 -> 0
A12: =IFERROR(__xludf.DUMMYFUNCTION("""COMPUTED_VALUE"""),45906.154997245365) -> 45906.155 | B12: =IFERROR(vlookup(A12,TSM!A:Q,2,FALSE),"") -> 45905 | C12: =IFERROR(vlookup(A12,TSM!A:Q,8,FALSE),"") -> 541880 | D12: =IFERROR(vlookup(A12,TSM!A:Q,10,FALSE),"") -> 509224 | E12: =IF(D11=C12,"Yes","No") -> Yes | F12: =C12-D11 -> 0 | H12: =IFERROR(__xludf.DUMMYFUNCTION("""COMPUTED_VALUE"""),45906.03527278935) -> 45906.035 | I12: =IFERROR(vlookup(H12,TSM!A:Q,2,FALSE),"") -> 45905 | J12: =IFERROR(vlookup(H12,TSM!A:Q,8,FALSE),"") -> 310349 | K12: =IFERROR(vlookup(H12,TSM!A:Q,10,FALSE),"") -> 354961 | L12: =IF(K11=J12,"Yes","No") -> Yes | M12: =J12-K11 -> 0 | O12: =IFERROR(__xludf.DUMMYFUNCTION("""COMPUTED_VALUE"""),45919.05942055555) -> 45919.059 | P12: =IFERROR(vlookup(O12,TSM!A:Q,2,FALSE),"") -> 45917 | Q12: =IFERROR(vlookup(O12,TSM!A:Q,8,FALSE),"") -> 403415 | R12: =IFERROR(vlookup(O12,TSM!A:Q,10,FALSE),"") -> 349053 | S12: =IF(R11=Q12,"Yes","No") -> Yes | T12: =R11-Q12 -> 0
A13: =IFERROR(__xludf.DUMMYFUNCTION("""COMPUTED_VALUE"""),45906.15610908565) -> 45906.156 | B13: =IFERROR(vlookup(A13,TSM!A:Q,2,FALSE),"") -> 45905 | C13: =IFERROR(vlookup(A13,TSM!A:Q,8,FALSE),"") -> 509224 | D13: =IFERROR(vlookup(A13,TSM!A:Q,10,FALSE),"") -> 479367 | E13: =IF(D12=C13,"Yes","No") -> Yes | F13: =C13-D12 -> 0 | H13: =IFERROR(__xludf.DUMMYFUNCTION("""COMPUTED_VALUE"""),45906.12240944445) -> 45906.122 | I13: =IFERROR(vlookup(H13,TSM!A:Q,2,FALSE),"") -> 45905 | J13: =IFERROR(vlookup(H13,TSM!A:Q,8,FALSE),"") -> 354961 | K13: =IFERROR(vlookup(H13,TSM!A:Q,10,FALSE),"") -> 400097 | L13: =IF(K12=J13,"Yes","No") -> Yes | M13: =J13-K12 -> 0 | O13: =IFERROR(__xludf.DUMMYFUNCTION("""COMPUTED_VALUE"""),45919.06393905093) -> 45919.064 | P13: =IFERROR(vlookup(O13,TSM!A:Q,2,FALSE),"") -> 45917 | Q13: =IFERROR(vlookup(O13,TSM!A:Q,8,FALSE),"") -> 349053 | R13: =IFERROR(vlookup(O13,TSM!A:Q,10,FALSE),"") -> 304713 | S13: =IF(R12=Q13,"Yes","No") -> Yes | T13: =R12-Q13 -> 0
A14: =IFERROR(__xludf.DUMMYFUNCTION("""COMPUTED_VALUE"""),45906.83074881944) -> 45906.831 | B14: =IFERROR(vlookup(A14,TSM!A:Q,2,FALSE),"") -> 45906 | C14: =IFERROR(vlookup(A14,TSM!A:Q,8,FALSE),"") -> 479367 | D14: =IFERROR(vlookup(A14,TSM!A:Q,10,FALSE),"") -> 453359 | E14: =IF(D13=C14,"Yes","No") -> Yes | F14: =C14-D13 -> 0 | H14: =IFERROR(__xludf.DUMMYFUNCTION("""COMPUTED_VALUE"""),45906.9832719213) -> 45906.983 | I14: =IFERROR(vlookup(H14,TSM!A:Q,2,FALSE),"") -> 45906 | J14: =IFERROR(vlookup(H14,TSM!A:Q,8,FALSE),"") -> 445440 | K14: =IFERROR(vlookup(H14,TSM!A:Q,10,FALSE),"") -> 489547 | L14: =IF(K13=J14,"Yes","No") -> No | M14: =J14-K13 -> 45343 | O14: =IFERROR(__xludf.DUMMYFUNCTION("""COMPUTED_VALUE"""),45919.06920243056) -> 45919.069 | P14: =IFERROR(vlookup(O14,TSM!A:Q,2,FALSE),"") -> 45918 | Q14: =IFERROR(vlookup(O14,TSM!A:Q,8,FALSE),"") -> 304197 | R14: =IFERROR(vlookup(O14,TSM!A:Q,10,FALSE),"") -> 283732 | S14: =IF(R13=Q14,"Yes","No") -> No | T14: =R13-Q14 -> 516
A15: =IFERROR(__xludf.DUMMYFUNCTION("""COMPUTED_VALUE"""),45906.83189854167) -> 45906.832 | B15: =IFERROR(vlookup(A15,TSM!A:Q,2,FALSE),"") -> 45906 | C15: =IFERROR(vlookup(A15,TSM!A:Q,8,FALSE),"") -> 453359 | D15: =IFERROR(vlookup(A15,TSM!A:Q,10,FALSE),"") -> 435537 | E15: =IF(D14=C15,"Yes","No") -> Yes | F15: =C15-D14 -> 0 | H15: =IFERROR(__xludf.DUMMYFUNCTION("""COMPUTED_VALUE"""),45906.9867652199) -> 45906.987 | I15: =IFERROR(vlookup(H15,TSM!A:Q,2,FALSE),"") -> 45906 | J15: =IFERROR(vlookup(H15,TSM!A:Q,8,FALSE),"") -> 489547 | K15: =IFERROR(vlookup(H15,TSM!A:Q,10,FALSE),"") -> 534353 | L15: =IF(K14=J15,"Yes","No") -> Yes | M15: =J15-K14 -> 0 | O15: =IFERROR(__xludf.DUMMYFUNCTION("""COMPUTED_VALUE"""),45919.36097150463) -> 45919.361 | P15: =IFERROR(vlookup(O15,TSM!A:Q,2,FALSE),"") -> 45918 | Q15: =IFERROR(vlookup(O15,TSM!A:Q,8,FALSE),"") -> 283732 | R15: =IFERROR(vlookup(O15,TSM!A:Q,10,FALSE),"") -> 268642 | S15: =IF(R14=Q15,"Yes","No") -> Yes | T15: =R14-Q15 -> 0
A16: =IFERROR(__xludf.DUMMYFUNCTION("""COMPUTED_VALUE"""),45906.98933898148) -> 45906.989 | B16: =IFERROR(vlookup(A16,TSM!A:Q,2,FALSE),"") -> 45906 | C16: =IFERROR(vlookup(A16,TSM!A:Q,8,FALSE),"") -> 435537 | D16: =IFERROR(vlookup(A16,TSM!A:Q,10,FALSE),"") -> 475741 | E16: =IF(D15=C16,"Yes","No") -> Yes | F16: =C16-D15 -> 0 | H16: =IFERROR(__xludf.DUMMYFUNCTION("""COMPUTED_VALUE"""),45906.9880784375) -> 45906.988 | I16: =IFERROR(vlookup(H16,TSM!A:Q,2,FALSE),"") -> 45906 | J16: =IFERROR(vlookup(H16,TSM!A:Q,8,FALSE),"") -> 534353 | K16: =IFERROR(vlookup(H16,TSM!A:Q,10,FALSE),"") -> 579603 | L16: =IF(K15=J16,"Yes","No") -> Yes | M16: =J16-K15 -> 0
A17: =IFERROR(__xludf.DUMMYFUNCTION("""COMPUTED_VALUE"""),45907.17284699074) -> 45907.173 | B17: =IFERROR(vlookup(A17,TSM!A:Q,2,FALSE),"") -> 45906 | C17: =IFERROR(vlookup(A17,TSM!A:Q,8,FALSE),"") -> 475741 | D17: =IFERROR(vlookup(A17,TSM!A:Q,10,FALSE),"") -> 519902 | E17: =IF(D16=C17,"Yes","No") -> Yes | F17: =C17-D16 -> 0 | H17: =IFERROR(__xludf.DUMMYFUNCTION("""COMPUTED_VALUE"""),45910.66157696759) -> 45910.662 | I17: =IFERROR(vlookup(H17,TSM!A:Q,2,FALSE),"") -> 45908 | J17: =IFERROR(vlookup(H17,TSM!A:Q,8,FALSE),"") -> 578044 | K17: =IFERROR(vlookup(H17,TSM!A:Q,10,FALSE),"") -> 552389 | L17: =IF(K16=J17,"Yes","No") -> No | M17: =J17-K16 -> -1559
A18: =IFERROR(__xludf.DUMMYFUNCTION("""COMPUTED_VALUE"""),45907.17419016204) -> 45907.174 | B18: =IFERROR(vlookup(A18,TSM!A:Q,2,FALSE),"") -> 45906 | C18: =IFERROR(vlookup(A18,TSM!A:Q,8,FALSE),"") -> 519902 | D18: =IFERROR(vlookup(A18,TSM!A:Q,10,FALSE),"") -> 564583 | E18: =IF(D17=C18,"Yes","No") -> Yes | F18: =C18-D17 -> 0 | H18: =IFERROR(__xludf.DUMMYFUNCTION("""COMPUTED_VALUE"""),45910.66252712963) -> 45910.663 | I18: =IFERROR(vlookup(H18,TSM!A:Q,2,FALSE),"") -> 45908 | J18: =IFERROR(vlookup(H18,TSM!A:Q,8,FALSE),"") -> 552389 | K18: =IFERROR(vlookup(H18,TSM!A:Q,10,FALSE),"") -> 514476 | L18: =IF(K17=J18,"Yes","No") -> Yes | M18: =J18-K17 -> 0
A19: =IFERROR(__xludf.DUMMYFUNCTION("""COMPUTED_VALUE"""),45907.217310844906) -> 45907.217 | B19: =IFERROR(vlookup(A19,TSM!A:Q,2,FALSE),"") -> 45906 | C19: =IFERROR(vlookup(A19,TSM!A:Q,8,FALSE),"") -> 564583 | D19: =IFERROR(vlookup(A19,TSM!A:Q,10,FALSE),"") -> 609473 | E19: =IF(D18=C19,"Yes","No") -> Yes | F19: =C19-D18 -> 0 | H19: =IFERROR(__xludf.DUMMYFUNCTION("""COMPUTED_VALUE"""),45910.66460023148) -> 45910.665 | I19: =IFERROR(vlookup(H19,TSM!A:Q,2,FALSE),"") -> 45908 | J19: =IFERROR(vlookup(H19,TSM!A:Q,8,FALSE),"") -> 514476 | K19: =IFERROR(vlookup(H19,TSM!A:Q,10,FALSE),"") -> 496506 | L19: =IF(K18=J19,"Yes","No") -> Yes | M19: =J19-K18 -> 0
A20: =IFERROR(__xludf.DUMMYFUNCTION("""COMPUTED_VALUE"""),45909.90931012732) -> 45909.909 | B20: =IFERROR(vlookup(A20,TSM!A:Q,2,FALSE),"") -> 45907 | C20: =IFERROR(vlookup(A20,TSM!A:Q,8,FALSE),"") -> 609473 | D20: =IFERROR(vlookup(A20,TSM!A:Q,10,FALSE),"") -> 650435 | E20: =IF(D19=C20,"Yes","No") -> Yes | F20: =C20-D19 -> 0 | H20: =IFERROR(__xludf.DUMMYFUNCTION("""COMPUTED_VALUE"""),45910.665429699075) -> 45910.665 | I20: =IFERROR(vlookup(H20,TSM!A:Q,2,FALSE),"") -> 45908 | J20: =IFERROR(vlookup(H20,TSM!A:Q,8,FALSE),"") -> 496506 | K20: =IFERROR(vlookup(H20,TSM!A:Q,10,FALSE),"") -> 461523 | L20: =IF(K19=J20,"Yes","No") -> Yes | M20: =J20-K19 -> 0
A21: =IFERROR(__xludf.DUMMYFUNCTION("""COMPUTED_VALUE"""),45909.91237359954) -> 45909.912 | B21: =IFERROR(vlookup(A21,TSM!A:Q,2,FALSE),"") -> 45907 | C21: =IFERROR(vlookup(A21,TSM!A:Q,8,FALSE),"") -> 650435 | D21: =IFERROR(vlookup(A21,TSM!A:Q,10,FALSE),"") -> 636634 | E21: =IF(D20=C21,"Yes","No") -> Yes | F21: =C21-D20 -> 0 | H21: =IFERROR(__xludf.DUMMYFUNCTION("""COMPUTED_VALUE"""),45910.6662864699) -> 45910.666 | I21: =IFERROR(vlookup(H21,TSM!A:Q,2,FALSE),"") -> 45908 | J21: =IFERROR(vlookup(H21,TSM!A:Q,8,FALSE),"") -> 461523 | K21: =IFERROR(vlookup(H21,TSM!A:Q,10,FALSE),"") -> 408294 | L21: =IF(K20=J21,"Yes","No") -> Yes | M21: =J21-K20 -> 0
A22: =IFERROR(__xludf.DUMMYFUNCTION("""COMPUTED_VALUE"""),45909.915909131945) -> 45909.916 | B22: =IFERROR(vlookup(A22,TSM!A:Q,2,FALSE),"") -> 45907 | C22: =IFERROR(vlookup(A22,TSM!A:Q,8,FALSE),"") -> 636634 | D22: =IFERROR(vlookup(A22,TSM!A:Q,10,FALSE),"") -> 605637 | E22: =IF(D21=C22,"Yes","No") -> Yes | F22: =C22-D21 -> 0 | H22: =IFERROR(__xludf.DUMMYFUNCTION("""COMPUTED_VALUE"""),45910.667109814814) -> 45910.667 | I22: =IFERROR(vlookup(H22,TSM!A:Q,2,FALSE),"") -> 45908 | J22: =IFERROR(vlookup(H22,TSM!A:Q,8,FALSE),"") -> 408294 | K22: =IFERROR(vlookup(H22,TSM!A:Q,10,FALSE),"") -> 368657 | L22: =IF(K21=J22,"Yes","No") -> Yes | M22: =J22-K21 -> 0
A23: =IFERROR(__xludf.DUMMYFUNCTION("""COMPUTED_VALUE"""),45909.917992835646) -> 45909.918 | B23: =IFERROR(vlookup(A23,TSM!A:Q,2,FALSE),"") -> 45907 | C23: =IFERROR(vlookup(A23,TSM!A:Q,8,FALSE),"") -> 605637 | D23: =IFERROR(vlookup(A23,TSM!A:Q,10,FALSE),"") -> 574639 | E23: =IF(D22=C23,"Yes","No") -> Yes | F23: =C23-D22 -> 0 | H23: =IFERROR(__xludf.DUMMYFUNCTION("""COMPUTED_VALUE"""),45910.669558298614) -> 45910.67 | I23: =IFERROR(vlookup(H23,TSM!A:Q,2,FALSE),"") -> 45908 | J23: =IFERROR(vlookup(H23,TSM!A:Q,8,FALSE),"") -> 368657 | K23: =IFERROR(vlookup(H23,TSM!A:Q,10,FALSE),"") -> 314498 | L23: =IF(K22=J23,"Yes","No") -> Yes | M23: =J23-K22 -> 0
A24: =IFERROR(__xludf.DUMMYFUNCTION("""COMPUTED_VALUE"""),45909.919386574074) -> 45909.919 | B24: =IFERROR(vlookup(A24,TSM!A:Q,2,FALSE),"") -> 45907 | C24: =IFERROR(vlookup(A24,TSM!A:Q,8,FALSE),"") -> 574639 | D24: =IFERROR(vlookup(A24,TSM!A:Q,10,FALSE),"") -> 562614 | E24: =IF(D23=C24,"Yes","No") -> Yes | F24: =C24-D23 -> 0 | H24: =IFERROR(__xludf.DUMMYFUNCTION("""COMPUTED_VALUE"""),45910.67212459491) -> 45910.672 | I24: =IFERROR(vlookup(H24,TSM!A:Q,2,FALSE),"") -> 45909 | J24: =IFERROR(vlookup(H24,TSM!A:Q,8,FALSE),"") -> 314498 | K24: =IFERROR(vlookup(H24,TSM!A:Q,10,FALSE),"") -> 259628 | L24: =IF(K23=J24,"Yes","No") -> Yes | M24: =J24-K23 -> 0
A25: =IFERROR(__xludf.DUMMYFUNCTION("""COMPUTED_VALUE"""),45909.92155613426) -> 45909.922 | B25: =IFERROR(vlookup(A25,TSM!A:Q,2,FALSE),"") -> 45907 | C25: =IFERROR(vlookup(A25,TSM!A:Q,8,FALSE),"") -> 562614 | D25: =IFERROR(vlookup(A25,TSM!A:Q,10,FALSE),"") -> 604496 | E25: =IF(D24=C25,"Yes","No") -> Yes | F25: =C25-D24 -> 0 | H25: =IFERROR(__xludf.DUMMYFUNCTION("""COMPUTED_VALUE"""),45918.41092775463) -> 45918.411 | I25: =IFERROR(vlookup(H25,TSM!A:Q,2,FALSE),"") -> 45913 | J25: =IFERROR(vlookup(H25,TSM!A:Q,8,FALSE),"") -> 259421 | K25: =IFERROR(vlookup(H25,TSM!A:Q,10,FALSE),"") -> 223118 | L25: =IF(K24=J25,"Yes","No") -> No | M25: =J25-K24 -> -207
A26: =IFERROR(__xludf.DUMMYFUNCTION("""COMPUTED_VALUE"""),45909.92390645834) -> 45909.924 | B26: =IFERROR(vlookup(A26,TSM!A:Q,2,FALSE),"") -> 45907 | C26: =IFERROR(vlookup(A26,TSM!A:Q,8,FALSE),"") -> 604496 | D26: =IFERROR(vlookup(A26,TSM!A:Q,10,FALSE),"") -> 648982 | E26: =IF(D25=C26,"Yes","No") -> Yes | F26: =C26-D25 -> 0 | H26: =IFERROR(__xludf.DUMMYFUNCTION("""COMPUTED_VALUE"""),45918.41367995371) -> 45918.414 | I26: =IFERROR(vlookup(H26,TSM!A:Q,2,FALSE),"") -> 45913 | J26: =IFERROR(vlookup(H26,TSM!A:Q,8,FALSE),"") -> 223118 | K26: =IFERROR(vlookup(H26,TSM!A:Q,10,FALSE),"") -> 197913 | L26: =IF(K25=J26,"Yes","No") -> Yes | M26: =J26-K25 -> 0
A27: =IFERROR(__xludf.DUMMYFUNCTION("""COMPUTED_VALUE"""),45909.92719778935) -> 45909.927 | B27: =IFERROR(vlookup(A27,TSM!A:Q,2,FALSE),"") -> 45908 | C27: =IFERROR(vlookup(A27,TSM!A:Q,8,FALSE),"") -> 648982 | D27: =IFERROR(vlookup(A27,TSM!A:Q,10,FALSE),"") -> 693707 | E27: =IF(D26=C27,"Yes","No") -> Yes | F27: =C27-D26 -> 0 | H27: =IFERROR(__xludf.DUMMYFUNCTION("""COMPUTED_VALUE"""),45918.41572592592) -> 45918.416 | I27: =IFERROR(vlookup(H27,TSM!A:Q,2,FALSE),"") -> 45913 | J27: =IFERROR(vlookup(H27,TSM!A:Q,8,FALSE),"") -> 197913 | K27: =IFERROR(vlookup(H27,TSM!A:Q,10,FALSE),"") -> 179554 | L27: =IF(K26=J27,"Yes","No") -> Yes | M27: =J27-K26 -> 0
A28: =IFERROR(__xludf.DUMMYFUNCTION("""COMPUTED_VALUE"""),45910.673613437495) -> 45910.674 | B28: =IFERROR(vlookup(A28,TSM!A:Q,2,FALSE),"") -> 45909 | C28: =IFERROR(vlookup(A28,TSM!A:Q,8,FALSE),"") -> 692877 | D28: =IFERROR(vlookup(A28,TSM!A:Q,10,FALSE),"") -> 662058 | E28: =IF(D27=C28,"Yes","No") -> No | F28: =C28-D27 -> -830 | H28: =IFERROR(__xludf.DUMMYFUNCTION("""COMPUTED_VALUE"""),45918.41967015046) -> 45918.42 | I28: =IFERROR(vlookup(H28,TSM!A:Q,2,FALSE),"") -> 45914 | J28: =IFERROR(vlookup(H28,TSM!A:Q,8,FALSE),"") -> 179554 | K28: =IFERROR(vlookup(H28,TSM!A:Q,10,FALSE),"") -> 137344 | L28: =IF(K27=J28,"Yes","No") -> Yes | M28: =J28-K27 -> 0
A29: =IFERROR(__xludf.DUMMYFUNCTION("""COMPUTED_VALUE"""),45910.67495170139) -> 45910.675 | B29: =IFERROR(vlookup(A29,TSM!A:Q,2,FALSE),"") -> 45909 | C29: =IFERROR(vlookup(A29,TSM!A:Q,8,FALSE),"") -> 662058 | D29: =IFERROR(vlookup(A29,TSM!A:Q,10,FALSE),"") -> 638918 | E29: =IF(D28=C29,"Yes","No") -> Yes | F29: =C29-D28 -> 0 | H29: =IFERROR(__xludf.DUMMYFUNCTION("""COMPUTED_VALUE"""),45918.433365370365) -> 45918.433 | I29: =IFERROR(vlookup(H29,TSM!A:Q,2,FALSE),"") -> 45914 | J29: =IFERROR(vlookup(H29,TSM!A:Q,8,FALSE),"") -> 137344 | K29: =IFERROR(vlookup(H29,TSM!A:Q,10,FALSE),"") -> 93859 | L29: =IF(K28=J29,"Yes","No") -> Yes | M29: =J29-K28 -> 0
A30: =IFERROR(__xludf.DUMMYFUNCTION("""COMPUTED_VALUE"""),45910.676013599536) -> 45910.676 | B30: =IFERROR(vlookup(A30,TSM!A:Q,2,FALSE),"") -> 45909 | C30: =IFERROR(vlookup(A30,TSM!A:Q,8,FALSE),"") -> 638918 | D30: =IFERROR(vlookup(A30,TSM!A:Q,10,FALSE),"") -> 678867 | E30: =IF(D29=C30,"Yes","No") -> Yes | F30: =C30-D29 -> 0 | H30: =IFERROR(__xludf.DUMMYFUNCTION("""COMPUTED_VALUE"""),45918.43495597222) -> 45918.435 | I30: =IFERROR(vlookup(H30,TSM!A:Q,2,FALSE),"") -> 45914 | J30: =IFERROR(vlookup(H30,TSM!A:Q,8,FALSE),"") -> 93859 | K30: =IFERROR(vlookup(H30,TSM!A:Q,10,FALSE),"") -> 50924 | L30: =IF(K29=J30,"Yes","No") -> Yes | M30: =J30-K29 -> 0
A31: =IFERROR(__xludf.DUMMYFUNCTION("""COMPUTED_VALUE"""),45910.67779840278) -> 45910.678 | B31: =IFERROR(vlookup(A31,TSM!A:Q,2,FALSE),"") -> 45909 | C31: =IFERROR(vlookup(A31,TSM!A:Q,8,FALSE),"") -> 678867 | D31: =IFERROR(vlookup(A31,TSM!A:Q,10,FALSE),"") -> 657596 | E31: =IF(D30=C31,"Yes","No") -> Yes | F31: =C31-D30 -> 0 | H31: =IFERROR(__xludf.DUMMYFUNCTION("""COMPUTED_VALUE"""),45918.436784074074) -> 45918.437 | I31: =IFERROR(vlookup(H31,TSM!A:Q,2,FALSE),"") -> 45914 | J31: =IFERROR(vlookup(H31,TSM!A:Q,8,FALSE),"") -> 50924 | K31: =IFERROR(vlookup(H31,TSM!A:Q,10,FALSE),"") -> 34179 | L31: =IF(K30=J31,"Yes","No") -> Yes | M31: =J31-K30 -> 0
A32: =IFERROR(__xludf.DUMMYFUNCTION("""COMPUTED_VALUE"""),45910.67933680555) -> 45910.679 | B32: =IFERROR(vlookup(A32,TSM!A:Q,2,FALSE),"") -> 45909 | C32: =IFERROR(vlookup(A32,TSM!A:Q,8,FALSE),"") -> 657596 | D32: =IFERROR(vlookup(A32,TSM!A:Q,10,FALSE),"") -> 607503 | E32: =IF(D31=C32,"Yes","No") -> Yes | F32: =C32-D31 -> 0 | H32: =IFERROR(__xludf.DUMMYFUNCTION("""COMPUTED_VALUE"""),45918.44258210648) -> 45918.443 | I32: =IFERROR(vlookup(H32,TSM!A:Q,2,FALSE),"") -> 45915 | J32: =IFERROR(vlookup(H32,TSM!A:Q,8,FALSE),"") -> 34179 | K32: =IFERROR(vlookup(H32,TSM!A:Q,10,FALSE),"") -> 29193 | L32: =IF(K31=J32,"Yes","No") -> Yes | M32: =J32-K31 -> 0
A33: =IFERROR(__xludf.DUMMYFUNCTION("""COMPUTED_VALUE"""),45910.68004998843) -> 45910.68 | B33: =IFERROR(vlookup(A33,TSM!A:Q,2,FALSE),"") -> 45909 | C33: =IFERROR(vlookup(A33,TSM!A:Q,8,FALSE),"") -> 607503 | D33: =IFERROR(vlookup(A33,TSM!A:Q,10,FALSE),"") -> 554424 | E33: =IF(D32=C33,"Yes","No") -> Yes | F33: =C33-D32 -> 0 | H33: =IFERROR(__xludf.DUMMYFUNCTION("""COMPUTED_VALUE"""),45918.45697508102) -> 45918.457 | I33: =IFERROR(vlookup(H33,TSM!A:Q,2,FALSE),"") -> 45915 | J33: =IFERROR(vlookup(H33,TSM!A:Q,8,FALSE),"") -> 29193 | K33: =IFERROR(vlookup(H33,TSM!A:Q,10,FALSE),"") -> 0 | L33: =IF(K32=J33,"Yes","No") -> Yes | M33: =J33-K32 -> 0
A34: =IFERROR(__xludf.DUMMYFUNCTION("""COMPUTED_VALUE"""),45910.68171280093) -> 45910.682 | B34: =IFERROR(vlookup(A34,TSM!A:Q,2,FALSE),"") -> 45909 | C34: =IFERROR(vlookup(A34,TSM!A:Q,8,FALSE),"") -> 554424 | D34: =IFERROR(vlookup(A34,TSM!A:Q,10,FALSE),"") -> 526433 | E34: =IF(D33=C34,"Yes","No") -> Yes | F34: =C34-D33 -> 0 | H34: =IFERROR(__xludf.DUMMYFUNCTION("""COMPUTED_VALUE"""),45919.067930798614) -> 45919.068 | I34: =IFERROR(vlookup(H34,TSM!A:Q,2,FALSE),"") -> 45918 | J34: =IFERROR(vlookup(H34,TSM!A:Q,8,FALSE),"") -> 34179 | K34: =IFERROR(vlookup(H34,TSM!A:Q,10,FALSE),"") -> 0 | L34: =IF(K33=J34,"Yes","No") -> No | M34: =J34-K33 -> 34179
A35: =IFERROR(__xludf.DUMMYFUNCTION("""COMPUTED_VALUE"""),45910.84531791667) -> 45910.845 | B35: =IFERROR(vlookup(A35,TSM!A:Q,2,FALSE),"") -> 45910 | C35: =IFERROR(vlookup(A35,TSM!A:Q,8,FALSE),"") -> 526433 | D35: =IFERROR(vlookup(A35,TSM!A:Q,10,FALSE),"") -> 485898 | E35: =IF(D34=C35,"Yes","No") -> Yes | F35: =C35-D34 -> 0 | I35: =IFERROR(vlookup(H35,TSM!A:Q,2,FALSE),"") | J35: =IFERROR(vlookup(H35,TSM!A:Q,8,FALSE),"") | K35: =IFERROR(vlookup(H35,TSM!A:Q,10,FALSE),"") | M35: =J35-K34 -> 0
A36: =IFERROR(__xludf.DUMMYFUNCTION("""COMPUTED_VALUE"""),45910.8466731713) -> 45910.847 | B36: =IFERROR(vlookup(A36,TSM!A:Q,2,FALSE),"") -> 45910 | C36: =IFERROR(vlookup(A36,TSM!A:Q,8,FALSE),"") -> 485898 | D36: =IFERROR(vlookup(A36,TSM!A:Q,10,FALSE),"") -> 435848 | E36: =IF(D35=C36,"Yes","No") -> Yes | F36: =C36-D35 -> 0 | I36: =IFERROR(vlookup(H36,TSM!A:Q,2,FALSE),"") | J36: =IFERROR(vlookup(H36,TSM!A:Q,8,FALSE),"") | K36: =IFERROR(vlookup(H36,TSM!A:Q,10,FALSE),"") | M36: =J36-K35 -> 0
A37: =IFERROR(__xludf.DUMMYFUNCTION("""COMPUTED_VALUE"""),45910.8475044213) -> 45910.848 | B37: =IFERROR(vlookup(A37,TSM!A:Q,2,FALSE),"") -> 45910 | C37: =IFERROR(vlookup(A37,TSM!A:Q,8,FALSE),"") -> 435848 | D37: =IFERROR(vlookup(A37,TSM!A:Q,10,FALSE),"") -> 387666 | E37: =IF(D36=C37,"Yes","No") -> Yes | F37: =C37-D36 -> 0 | I37: =IFERROR(vlookup(H37,TSM!A:Q,2,FALSE),"") | J37: =IFERROR(vlookup(H37,TSM!A:Q,8,FALSE),"") | K37: =IFERROR(vlookup(H37,TSM!A:Q,10,FALSE),"") | M37: =J37-K36 -> 0
A38: =IFERROR(__xludf.DUMMYFUNCTION("""COMPUTED_VALUE"""),45910.85925925926) -> 45910.859 | B38: =IFERROR(vlookup(A38,TSM!A:Q,2,FALSE),"") -> 45910 | C38: =IFERROR(vlookup(A38,TSM!A:Q,8,FALSE),"") -> 387666 | D38: =IFERROR(vlookup(A38,TSM!A:Q,10,FALSE),"") -> 358445 | E38: =IF(D37=C38,"Yes","No") -> Yes | F38: =C38-D37 -> 0 | I38: =IFERROR(vlookup(H38,TSM!A:Q,2,FALSE),"") | J38: =IFERROR(vlookup(H38,TSM!A:Q,8,FALSE),"") | K38: =IFERROR(vlookup(H38,TSM!A:Q,10,FALSE),"") | M38: =J38-K37 -> 0
A39: =IFERROR(__xludf.DUMMYFUNCTION("""COMPUTED_VALUE"""),45918.08610627315) -> 45918.086 | B39: =IFERROR(vlookup(A39,TSM!A:Q,2,FALSE),"") -> 45910 | C39: =IFERROR(vlookup(A39,TSM!A:Q,8,FALSE),"") -> 358445 | D39: =IFERROR(vlookup(A39,TSM!A:Q,10,FALSE),"") -> 325806 | E39: =IF(D38=C39,"Yes","No") -> Yes | F39: =C39-D38 -> 0 | I39: =IFERROR(vlookup(H39,TSM!A:Q,2,FALSE),"") | J39: =IFERROR(vlookup(H39,TSM!A:Q,8,FALSE),"") | K39: =IFERROR(vlookup(H39,TSM!A:Q,10,FALSE),"") | M39: =J39-K38 -> 0
A40: =IFERROR(__xludf.DUMMYFUNCTION("""COMPUTED_VALUE"""),45918.088120810186) -> 45918.088 | B40: =IFERROR(vlookup(A40,TSM!A:Q,2,FALSE),"") -> 45910 | C40: =IFERROR(vlookup(A40,TSM!A:Q,8,FALSE),"") -> 325806 | D40: =IFERROR(vlookup(A40,TSM!A:Q,10,FALSE),"") -> 282716 | E40: =IF(D39=C40,"Yes","No") -> Yes | F40: =C40-D39 -> 0 | I40: =IFERROR(vlookup(H40,TSM!A:Q,2,FALSE),"") | J40: =IFERROR(vlookup(H40,TSM!A:Q,8,FALSE),"") | K40: =IFERROR(vlookup(H40,TSM!A:Q,10,FALSE),"") | M40: =J40-K39 -> 0
...

Sheet Sheet8

Sheet Sales
A1: Timestamp | B1: Date | C1: Month | D1: Year | E1: Equipment | F1: Airline | G1: Aircraft Category | H1: Aircraft Number | I1: Uplift | J1: ADI Number
